/var/lib/condor/execute/dir_2534164/run_training.sh: line 15: venv/bin/activate: No such file or directory
  WARNING: The scripts pip, pip3 and pip3.8 are installed in '/var/lib/condor/execute/dir_2534164/.local/bin' which is not on PATH.
  Consider adding this directory to PATH or, if you prefer to suppress this warning, use --no-warn-script-location.

[notice] A new release of pip is available: 24.2 -> 24.3.1
[notice] To update, run: python3 -m pip install --upgrade pip
  error: subprocess-exited-with-error
  
  × Building wheel for XRootD (pyproject.toml) did not run successfully.
  │ exit code: 1
  ╰─> [137 lines of output]
      running bdist_wheel
      running build
      running build_py
      creating build/lib.linux-x86_64-cpython-38/XRootD
      copying bindings/python/libs/__init__.py -> build/lib.linux-x86_64-cpython-38/XRootD
      creating build/lib.linux-x86_64-cpython-38/XRootD/client
      copying bindings/python/libs/client/file.py -> build/lib.linux-x86_64-cpython-38/XRootD/client
      copying bindings/python/libs/client/__init__.py -> build/lib.linux-x86_64-cpython-38/XRootD/client
      copying bindings/python/libs/client/finalize.py -> build/lib.linux-x86_64-cpython-38/XRootD/client
      copying bindings/python/libs/client/filesystem.py -> build/lib.linux-x86_64-cpython-38/XRootD/client
      copying bindings/python/libs/client/copyprocess.py -> build/lib.linux-x86_64-cpython-38/XRootD/client
      copying bindings/python/libs/client/glob_funcs.py -> build/lib.linux-x86_64-cpython-38/XRootD/client
      copying bindings/python/libs/client/responses.py -> build/lib.linux-x86_64-cpython-38/XRootD/client
      copying bindings/python/libs/client/env.py -> build/lib.linux-x86_64-cpython-38/XRootD/client
      copying bindings/python/libs/client/utils.py -> build/lib.linux-x86_64-cpython-38/XRootD/client
      copying bindings/python/libs/client/_version.py -> build/lib.linux-x86_64-cpython-38/XRootD/client
      copying bindings/python/libs/client/flags.py -> build/lib.linux-x86_64-cpython-38/XRootD/client
      copying bindings/python/libs/client/url.py -> build/lib.linux-x86_64-cpython-38/XRootD/client
      creating build/lib.linux-x86_64-cpython-38/pyxrootd
      copying bindings/python/src/__init__.py -> build/lib.linux-x86_64-cpython-38/pyxrootd
      running build_ext
      -- The C compiler identification is GNU 9.4.0
      -- The CXX compiler identification is GNU 9.4.0
      -- Check for working C compiler: /usr/bin/cc
      -- Check for working C compiler: /usr/bin/cc -- works
      -- Detecting C compiler ABI info
      -- Detecting C compiler ABI info - done
      -- Detecting C compile features
      -- Detecting C compile features - done
      -- Check for working CXX compiler: /usr/bin/c++
      -- Check for working CXX compiler: /usr/bin/c++ -- works
      -- Detecting CXX compiler ABI info
      -- Detecting CXX compiler ABI info - done
      -- Detecting CXX compile features
      -- Detecting CXX compile features - done
      -- Looking for setresuid
      -- Looking for setresuid - found
      -- Looking for strlcpy
      -- Looking for strlcpy - not found
      -- Looking for fstatat
      -- Looking for fstatat - found
      -- Looking for sigwaitinfo
      -- Looking for sigwaitinfo - found
      -- Looking for shadow.h
      -- Looking for shadow.h - found
      -- Looking for getifaddrs
      -- Looking for getifaddrs - found
      -- Looking for getnameinfo
      -- Looking for getnameinfo - found
      -- Looking for getprotobyname_r
      -- Looking for getprotobyname_r - found
      -- Looking for gethostbyaddr_r
      -- Looking for gethostbyaddr_r - found
      -- Looking for sendfile
      -- Looking for sendfile - found
      -- Looking for crypt
      -- Looking for crypt - not found
      -- Looking for crypt in crypt
      -- Looking for crypt in crypt - found
      -- Looking for et/com_err.h
      -- Looking for et/com_err.h - not found
      -- Looking for pthread.h
      -- Looking for pthread.h - found
      -- Performing Test CMAKE_HAVE_LIBC_PTHREAD
      -- Performing Test CMAKE_HAVE_LIBC_PTHREAD - Failed
      -- Check if compiler accepts -pthread
      -- Check if compiler accepts -pthread - yes
      -- Found Threads: TRUE
      -- Performing Test HAVE_ATOMICS
      -- Performing Test HAVE_ATOMICS - Success
      -- Performing Test HAVE_CXX_ATOMICS_WITHOUT_LIB
      -- Performing Test HAVE_CXX_ATOMICS_WITHOUT_LIB - Success
      -- Found ZLIB: /usr/lib/x86_64-linux-gnu/libz.so (found version "1.2.11")
      CMake Error at /usr/share/cmake-3.16/Modules/FindPackageHandleStandardArgs.cmake:146 (message):
        Could NOT find libuuid (missing: UUID_INCLUDE_DIR UUID_LIBRARY)
      Call Stack (most recent call first):
        /usr/share/cmake-3.16/Modules/FindPackageHandleStandardArgs.cmake:393 (_FPHSA_FAILURE_MESSAGE)
        cmake/Findlibuuid.cmake:91 (find_package_handle_standard_args)
        cmake/XRootDFindLibs.cmake:6 (find_package)
        CMakeLists.txt:28 (include)
      
      
      -- Configuring incomplete, errors occurred!
      See also "/var/lib/condor/execute/dir_2534164/pip-install-vdttril0/xrootd_287b3f79601c464bbd12596c75007f0d/build/temp.linux-x86_64-cpython-38/CMakeFiles/CMakeOutput.log".
      See also "/var/lib/condor/execute/dir_2534164/pip-install-vdttril0/xrootd_287b3f79601c464bbd12596c75007f0d/build/temp.linux-x86_64-cpython-38/CMakeFiles/CMakeError.log".
      Traceback (most recent call last):
        File "/var/lib/condor/execute/dir_2534164/.local/lib/python3.8/site-packages/pip/_vendor/pyproject_hooks/_in_process/_in_process.py", line 353, in <module>
          main()
        File "/var/lib/condor/execute/dir_2534164/.local/lib/python3.8/site-packages/pip/_vendor/pyproject_hooks/_in_process/_in_process.py", line 335, in main
          json_out['return_val'] = hook(**hook_input['kwargs'])
        File "/var/lib/condor/execute/dir_2534164/.local/lib/python3.8/site-packages/pip/_vendor/pyproject_hooks/_in_process/_in_process.py", line 251, in build_wheel
          return _build_backend().build_wheel(wheel_directory, config_settings,
        File "/var/lib/condor/execute/dir_2534164/pip-build-env-l_p2r_l2/overlay/lib/python3.8/site-packages/setuptools/build_meta.py", line 437, in build_wheel
          return _build(['bdist_wheel', '--dist-info-dir', str(metadata_directory)])
        File "/var/lib/condor/execute/dir_2534164/pip-build-env-l_p2r_l2/overlay/lib/python3.8/site-packages/setuptools/build_meta.py", line 425, in _build
          return self._build_with_temp_dir(
        File "/var/lib/condor/execute/dir_2534164/pip-build-env-l_p2r_l2/overlay/lib/python3.8/site-packages/setuptools/build_meta.py", line 406, in _build_with_temp_dir
          self.run_setup()
        File "/var/lib/condor/execute/dir_2534164/pip-build-env-l_p2r_l2/overlay/lib/python3.8/site-packages/setuptools/build_meta.py", line 319, in run_setup
          exec(code, locals())
        File "<string>", line 94, in <module>
        File "/var/lib/condor/execute/dir_2534164/pip-build-env-l_p2r_l2/overlay/lib/python3.8/site-packages/setuptools/__init__.py", line 117, in setup
          return distutils.core.setup(**attrs)
        File "/var/lib/condor/execute/dir_2534164/pip-build-env-l_p2r_l2/overlay/lib/python3.8/site-packages/setuptools/_distutils/core.py", line 183, in setup
          return run_commands(dist)
        File "/var/lib/condor/execute/dir_2534164/pip-build-env-l_p2r_l2/overlay/lib/python3.8/site-packages/setuptools/_distutils/core.py", line 199, in run_commands
          dist.run_commands()
        File "/var/lib/condor/execute/dir_2534164/pip-build-env-l_p2r_l2/overlay/lib/python3.8/site-packages/setuptools/_distutils/dist.py", line 954, in run_commands
          self.run_command(cmd)
        File "/var/lib/condor/execute/dir_2534164/pip-build-env-l_p2r_l2/overlay/lib/python3.8/site-packages/setuptools/dist.py", line 999, in run_command
          super().run_command(command)
        File "/var/lib/condor/execute/dir_2534164/pip-build-env-l_p2r_l2/overlay/lib/python3.8/site-packages/setuptools/_distutils/dist.py", line 973, in run_command
          cmd_obj.run()
        File "/var/lib/condor/execute/dir_2534164/pip-build-env-l_p2r_l2/overlay/lib/python3.8/site-packages/setuptools/command/bdist_wheel.py", line 410, in run
          self.run_command("build")
        File "/var/lib/condor/execute/dir_2534164/pip-build-env-l_p2r_l2/overlay/lib/python3.8/site-packages/setuptools/_distutils/cmd.py", line 316, in run_command
          self.distribution.run_command(command)
        File "/var/lib/condor/execute/dir_2534164/pip-build-env-l_p2r_l2/overlay/lib/python3.8/site-packages/setuptools/dist.py", line 999, in run_command
          super().run_command(command)
        File "/var/lib/condor/execute/dir_2534164/pip-build-env-l_p2r_l2/overlay/lib/python3.8/site-packages/setuptools/_distutils/dist.py", line 973, in run_command
          cmd_obj.run()
        File "/var/lib/condor/execute/dir_2534164/pip-build-env-l_p2r_l2/overlay/lib/python3.8/site-packages/setuptools/_distutils/command/build.py", line 135, in run
          self.run_command(cmd_name)
        File "/var/lib/condor/execute/dir_2534164/pip-build-env-l_p2r_l2/overlay/lib/python3.8/site-packages/setuptools/_distutils/cmd.py", line 316, in run_command
          self.distribution.run_command(command)
        File "/var/lib/condor/execute/dir_2534164/pip-build-env-l_p2r_l2/overlay/lib/python3.8/site-packages/setuptools/dist.py", line 999, in run_command
          super().run_command(command)
        File "/var/lib/condor/execute/dir_2534164/pip-build-env-l_p2r_l2/overlay/lib/python3.8/site-packages/setuptools/_distutils/dist.py", line 973, in run_command
          cmd_obj.run()
        File "/var/lib/condor/execute/dir_2534164/pip-build-env-l_p2r_l2/overlay/lib/python3.8/site-packages/setuptools/command/build_ext.py", line 98, in run
          _build_ext.run(self)
        File "/var/lib/condor/execute/dir_2534164/pip-build-env-l_p2r_l2/overlay/lib/python3.8/site-packages/setuptools/_distutils/command/build_ext.py", line 359, in run
          self.build_extensions()
        File "<string>", line 89, in build_extensions
        File "/usr/lib/python3.8/subprocess.py", line 364, in check_call
          raise CalledProcessError(retcode, cmd)
      subprocess.CalledProcessError: Command '['/usr/bin/cmake', '/var/lib/condor/execute/dir_2534164/pip-install-vdttril0/xrootd_287b3f79601c464bbd12596c75007f0d', '-B', 'build/temp.linux-x86_64-cpython-38', '-DPython_EXECUTABLE=/usr/bin/python3', '-DCMAKE_BUILD_WITH_INSTALL_RPATH=TRUE', '-DCMAKE_ARCHIVE_OUTPUT_DIRECTORY=build/temp.linux-x86_64-cpython-38/pyxrootd', '-DCMAKE_LIBRARY_OUTPUT_DIRECTORY=/var/lib/condor/execute/dir_2534164/pip-install-vdttril0/xrootd_287b3f79601c464bbd12596c75007f0d/build/lib.linux-x86_64-cpython-38/pyxrootd', '-DENABLE_PYTHON=1', '-DENABLE_XRDCL=1', '-DXRDCL_LIB_ONLY=1', '-DPYPI_BUILD=1', '-DCMAKE_INSTALL_RPATH=$ORIGIN']' returned non-zero exit status 1.
      [end of output]
  
  note: This error originates from a subprocess, and is likely not a problem with pip.
  ERROR: Failed building wheel for XRootD
ERROR: ERROR: Failed to build installable wheels for some pyproject.toml based projects (XRootD)
/cvmfs/sft.cern.ch/lcg/releases/R/3.6.3-0846b/x86_64-centos7-gcc8-opt/lib64/R/bin/exec/R: error while loading shared libraries: libreadline.so.6: cannot open shared object file: No such file or directory
/cvmfs/sft.cern.ch/lcg/releases/R/3.6.3-0846b/x86_64-centos7-gcc8-opt/lib64/R/bin/exec/R: error while loading shared libraries: libreadline.so.6: cannot open shared object file: No such file or directory
/cvmfs/sft.cern.ch/lcg/releases/R/3.6.3-0846b/x86_64-centos7-gcc8-opt/lib64/R/bin/exec/R: error while loading shared libraries: libreadline.so.6: cannot open shared object file: No such file or directory
/cvmfs/sft.cern.ch/lcg/releases/R/3.6.3-0846b/x86_64-centos7-gcc8-opt/lib64/R/bin/exec/R: error while loading shared libraries: libreadline.so.6: cannot open shared object file: No such file or directory
/cvmfs/sft.cern.ch/lcg/releases/R/3.6.3-0846b/x86_64-centos7-gcc8-opt/lib64/R/bin/exec/R: error while loading shared libraries: libreadline.so.6: cannot open shared object file: No such file or directory
xrdcp: error while loading shared libraries: libssl.so.10: cannot open shared object file: No such file or directory
DGL backend not selected or invalid.  Assuming PyTorch for now.
Traceback (most recent call last):
  File "/usr/lib/python3.8/runpy.py", line 194, in _run_module_as_main
    return _run_code(code, main_globals, None,
  File "/usr/lib/python3.8/runpy.py", line 87, in _run_code
    exec(code, run_globals)
  File "/var/lib/condor/execute/dir_2534164/PID_GNN/src/train_lightning1.py", line 28, in <module>
    from src.utils.train_utils import (
  File "/var/lib/condor/execute/dir_2534164/PID_GNN/src/utils/train_utils.py", line 16, in <module>
    from src.dataset.dataset import SimpleIterDataset
  File "/var/lib/condor/execute/dir_2534164/PID_GNN/src/dataset/dataset.py", line 22, in <module>
    from src.dataset.functions_graph import create_graph
  File "/var/lib/condor/execute/dir_2534164/PID_GNN/src/dataset/functions_graph.py", line 3, in <module>
    import dgl
  File "/usr/local/lib/python3.8/dist-packages/dgl/__init__.py", line 16, in <module>
    from . import (
  File "/usr/local/lib/python3.8/dist-packages/dgl/dataloading/__init__.py", line 13, in <module>
    from .dataloader import *
  File "/usr/local/lib/python3.8/dist-packages/dgl/dataloading/dataloader.py", line 27, in <module>
    from ..distributed import DistGraph
  File "/usr/local/lib/python3.8/dist-packages/dgl/distributed/__init__.py", line 5, in <module>
    from .dist_graph import DistGraph, DistGraphServer, edge_split, node_split
  File "/usr/local/lib/python3.8/dist-packages/dgl/distributed/dist_graph.py", line 11, in <module>
    from .. import backend as F, graphbolt as gb, heterograph_index
  File "/usr/local/lib/python3.8/dist-packages/dgl/graphbolt/__init__.py", line 8, in <module>
    from .base import *
  File "/usr/local/lib/python3.8/dist-packages/dgl/graphbolt/base.py", line 8, in <module>
    from torchdata.datapipes.iter import IterDataPipe
  File "/usr/local/lib/python3.8/dist-packages/torchdata/datapipes/__init__.py", line 9, in <module>
    from torchdata import _extension  # noqa: F401
  File "/usr/local/lib/python3.8/dist-packages/torchdata/__init__.py", line 29, in __getattr__
    return importlib.import_module("." + name, __name__)
  File "/usr/lib/python3.8/importlib/__init__.py", line 127, in import_module
    return _bootstrap._gcd_import(name[level:], package, level)
  File "/usr/local/lib/python3.8/dist-packages/torchdata/_extension.py", line 34, in <module>
    _init_extension()
  File "/usr/local/lib/python3.8/dist-packages/torchdata/_extension.py", line 31, in _init_extension
    from torchdata import _torchdata as _torchdata
  File "/usr/local/lib/python3.8/dist-packages/torchdata/__init__.py", line 29, in __getattr__
    return importlib.import_module("." + name, __name__)
  File "/usr/lib/python3.8/importlib/__init__.py", line 127, in import_module
    return _bootstrap._gcd_import(name[level:], package, level)
ImportError: libssl.so.3: cannot open shared object file: No such file or directory
