/var/lib/condor/execute/dir_565935/run_training.sh: line 24: xrdcp: command not found
DGL backend not selected or invalid.  Assuming PyTorch for now.
Traceback (most recent call last):
  File "/usr/lib/python3.8/runpy.py", line 194, in _run_module_as_main
    return _run_code(code, main_globals, None,
  File "/usr/lib/python3.8/runpy.py", line 87, in _run_code
    exec(code, run_globals)
  File "/var/lib/condor/execute/dir_565935/PID_GNN/src/train_lightning1.py", line 28, in <module>
    from src.utils.train_utils import (
  File "/var/lib/condor/execute/dir_565935/PID_GNN/src/utils/train_utils.py", line 16, in <module>
    from src.dataset.dataset import SimpleIterDataset
  File "/var/lib/condor/execute/dir_565935/PID_GNN/src/dataset/dataset.py", line 22, in <module>
    from src.dataset.functions_graph import create_graph
  File "/var/lib/condor/execute/dir_565935/PID_GNN/src/dataset/functions_graph.py", line 3, in <module>
    import dgl
  File "/usr/local/lib/python3.8/dist-packages/dgl/__init__.py", line 16, in <module>
    from . import (
  File "/usr/local/lib/python3.8/dist-packages/dgl/dataloading/__init__.py", line 13, in <module>
    from .dataloader import *
  File "/usr/local/lib/python3.8/dist-packages/dgl/dataloading/dataloader.py", line 27, in <module>
    from ..distributed import DistGraph
  File "/usr/local/lib/python3.8/dist-packages/dgl/distributed/__init__.py", line 5, in <module>
    from .dist_graph import DistGraph, DistGraphServer, edge_split, node_split
  File "/usr/local/lib/python3.8/dist-packages/dgl/distributed/dist_graph.py", line 11, in <module>
    from .. import backend as F, graphbolt as gb, heterograph_index
  File "/usr/local/lib/python3.8/dist-packages/dgl/graphbolt/__init__.py", line 8, in <module>
    from .base import *
  File "/usr/local/lib/python3.8/dist-packages/dgl/graphbolt/base.py", line 8, in <module>
    from torchdata.datapipes.iter import IterDataPipe
  File "/usr/local/lib/python3.8/dist-packages/torchdata/datapipes/__init__.py", line 9, in <module>
    from torchdata import _extension  # noqa: F401
  File "/usr/local/lib/python3.8/dist-packages/torchdata/__init__.py", line 29, in __getattr__
    return importlib.import_module("." + name, __name__)
  File "/usr/lib/python3.8/importlib/__init__.py", line 127, in import_module
    return _bootstrap._gcd_import(name[level:], package, level)
  File "/usr/local/lib/python3.8/dist-packages/torchdata/_extension.py", line 34, in <module>
    _init_extension()
  File "/usr/local/lib/python3.8/dist-packages/torchdata/_extension.py", line 31, in _init_extension
    from torchdata import _torchdata as _torchdata
  File "/usr/local/lib/python3.8/dist-packages/torchdata/__init__.py", line 29, in __getattr__
    return importlib.import_module("." + name, __name__)
  File "/usr/lib/python3.8/importlib/__init__.py", line 127, in import_module
    return _bootstrap._gcd_import(name[level:], package, level)
ImportError: libssl.so.3: cannot open shared object file: No such file or directory
